Workbook

Sheet Inputs
B2: Model inputs
B3: Blue cells are inputs; edit these and every result recalculates. Low / Central / High are the sensitivity range used in Section 4.2.
B5: Parameter | C5: Low | D5: Central | E5: High | F5: Unit | G5: Source
B6: Installed IT capacity, 2031 | C6: 180 | D6: 200 | E6: 220 | F6: GW | G6: JLL (2026), Section 3.2; tested range of plus or minus 10%
B7: Server idle power share | C7: 0.2 | D7: 0.27 | E7: 0.36 | F7: fraction of maximum power | G7: Shehabi et al. (2024), LBNL, p. 27: conventional servers 36% (2023), 27% (2028); AI servers 20%. Central holds the 2028 value flat to 2031
B8: PUE | C8: 1.04 | D8: 1.3 | E8: 1.57 | F8: ratio | G8: Low: RAND new-build trajectory. Central: 2031 capacity shares applied to 1.15 (hyperscale, just below LBNL 2023 range 1.16-1.28) and 1.57 (rest) = 1.29, rounded. High: Uptime Institute fleet average. Section 3.2
B9: Grid carbon intensity | C9: 345 | D9: 395 | E9: 445 | F9: g CO2 per kWh | G9: High: IEA 2024 global average. Low: IEA 2025-2027 decline (~3.6%/yr) carried to 2031. Central: midpoint
B10: WUE (direct water) | C10: 0.32 | D10: 0.48 | E10: 1.8 | F10: L per kWh of IT energy | G10: Central: upper end of LBNL 2024 projected US average (p. 49). Low: LBNL 2024 hyperscale median (p. 48). High: LBNL 2016 average
B11: Base-year calibration factor (rho) | C11: =Calibration!$C$29 | D11: =Calibration!$C$29 | E11: 1 | F11: ratio | G11: Low and central: calibrated so the model reproduces the IEA's 2026 estimate (Calibration sheet, Eq. 7). High: no calibration (model as built)
B12: Constant | C12: Value | F12: Unit | G12: Source
B13: Hours per year | C13: 8760 | F13: hours | G13: 365 x 24
B14: LBNL series start year | C14: 2014 | F14: year | G14: Shehabi et al. (2024), p. 28
B15: LBNL series end year | C15: 2027 | F15: year | G15: Shehabi et al. (2024), p. 28
B16: Projection year | C16: 2031 | F16: year | G16: Section 3.2
B17: UNU-INWEH water footprint, 2030 | C17: 9.3 | F17: trillion litres | G17: UNU-INWEH (2026); direct plus electricity-generation water
B18: Energy basis of the UNU figure | C18: 945 | F18: TWh | G18: IEA 2030 base case, Sections 1 and 4.1
B19: S&P 2030 demand estimate | C19: 1587 | F19: TWh | G19: S&P Global 451 Research, Sections 1 and 4.1
B20: Committed nuclear capacity | C20: 9.8 | F20: GW | G20: SMR Intel (2026), Section 5.2
B21: Nuclear capacity factor | C21: 0.9 | F21: fraction | G21: Typical US fleet, Section 5.2

Sheet Utilisation
B2: Fleet utilisation and electrical load factor (Section 3.2)
B3: LBNL facility-type utilisation (operational time) extrapolated linearly to 2031, weighted by capacity share, then converted to electrical load with the idle share.
B5: Facility type | C5: 2014 | D5: 2027 | E5: Extrapolated 2031 | F5: Source
B6: Hyperscale | C6: 0.45 | D6: 0.5 | E6: =D6+(D6-C6)/(Inputs!$C$15-Inputs!$C$14)*(Inputs!$C$16-Inputs!$C$15) | F6: Shehabi et al. (2024), p. 28
B7: Colocation | C7: 0.21 | D7: 0.35 | E7: =D7+(D7-C7)/(Inputs!$C$15-Inputs!$C$14)*(Inputs!$C$16-Inputs!$C$15) | F7: Shehabi et al. (2024), p. 28
B8: Internal / small | C8: 0.11 | D8: 0.2 | E8: =D8+(D8-C8)/(Inputs!$C$15-Inputs!$C$14)*(Inputs!$C$16-Inputs!$C$15) | F8: Shehabi et al. (2024), p. 28
B10: Capacity-share scenario | C10: Hyperscale share | D10: Colocation share | E10: Internal / small share | F10: Weighted utilisation | G10: Load factor (central idle share) | H10: Note
B11: Slower consolidation (low) | C11: 0.6 | D11: 0.16969697 | E11: 0.23030303 | F11: =C11*$E$6+D11*$E$7+E11*$E$8 | G11: =Inputs!$D$7+(1-Inputs!$D$7)*F11 | H11: Hyperscale 60%, rest in the 2031 ratio 14:19 (assumption)
B12: Central (Synergy projection) | C12: 0.67 | D12: 0.14 | E12: 0.19 | F12: =C12*$E$6+D12*$E$7+E12*$E$8 | G12: =Inputs!$D$7+(1-Inputs!$D$7)*F12 | H12: Synergy Research Group (2026): hyperscale 67%, on-premises 19%, colocation 14% by difference
B13: All-hyperscale (high) | C13: 1 | D13: 0 | E13: 0 | F13: =C13*$E$6+D13*$E$7+E13*$E$8 | G13: =Inputs!$D$7+(1-Inputs!$D$7)*F13 | H13: Upper bound
B15: Check: shares sum to 100%
B16: Slower consolidation (low) | C16: =C11+D11+E11
B17: Central (Synergy projection) | C17: =C12+D12+E12
B18: All-hyperscale (high) | C18: =C13+D13+E13
B20: Load factor = idle share + (1 - idle share) x utilisation (Shehabi et al., 2024, pp. 18-19: linear interpolation between idle and maximum power)

Sheet Calibration
B2: Base-year check and calibration (Section 3.2, Eq. 7)
B3: Runs the model for 2026 and compares it with published estimates of 2026 use. rho = IEA 2026 estimate / model 2026 facility energy.
B5: Item | C5: Value | D5: Unit | E5: Source
B6: Installed IT capacity, start of 2026 | C6: 103 | D6: GW | E6: JLL (2026)
B7: Completions expected during 2025 | C7: 7 | D7: GW | E7: JLL (2025)
B8: Average installed capacity, 2025 | C8: =C6-C7/2 | D8: GW | E8: mid-year
B9: Hyperscale share, 2025 | C9: 0.48 | E9: Synergy Research Group (2026)
B10: Colocation share, 2025 | C10: 0.2 | E10: Synergy Research Group (2026)
B11: On-premises (internal) share, 2025 | C11: 0.32 | E11: Synergy Research Group (2026)
B12: Hyperscale utilisation, 2025 | C12: =Utilisation!$D$6+(Utilisation!$D$6-Utilisation!$C$6)/(Inputs!$C$15-Inputs!$C$14)*(2025-Inputs!$C$15) | E12: LBNL trend at 2025
B13: Colocation utilisation, 2025 | C13: =Utilisation!$D$7+(Utilisation!$D$7-Utilisation!$C$7)/(Inputs!$C$15-Inputs!$C$14)*(2025-Inputs!$C$15) | E13: LBNL trend at 2025
B14: Internal / small utilisation, 2025 | C14: =Utilisation!$D$8+(Utilisation!$D$8-Utilisation!$C$8)/(Inputs!$C$15-Inputs!$C$14)*(2025-Inputs!$C$15) | E14: LBNL trend at 2025
B15: Fleet utilisation, 2025 | C15: =C9*C12+C10*C13+C11*C14 | E15: capacity-weighted
B16: Idle share, 2023 | C16: 0.36 | D16: of max power | E16: Shehabi et al. (2024), p. 27
B17: Idle share, 2028 | C17: 0.27 | D17: of max power | E17: Shehabi et al. (2024), p. 27
B18: Idle share, 2025 | C18: =C16+(C17-C16)*2/5 | D18: of max power | E18: linear interpolation
B19: Load factor, 2025 | C19: =C18+(1-C18)*C15 | E19: Eq. 6
B20: PUE, 2025 | C20: 1.56 | E20: Uptime Institute (2024) fleet average
B21: Model facility energy, 2025 | C21: =C8*C19*Inputs!$C$13/1000*C20 | D21: TWh | E21: Eqs. 1-2 with rho = 1
B22: IEA data centre use, 2024 | C22: 415 | D22: TWh | E22: IEA (2025a)
B23: IEA growth in 2025 | C23: 0.17 | E23: IEA (2026)
B24: IEA estimate, 2025 | C24: =C22*(1+C23) | D24: TWh
B25: 451 Research, 2025 | C25: 860 | D25: TWh | E25: S&P Global (2025), includes crypto mining
B26: Model / IEA, 2025 | C26: =C21/C24 | D26: x
B27: Model / 451 Research, 2025 | C27: =C21/C25 | D27: x
B28: IEA energy per GW of capacity, 2025 | C28: =C24/C8 | D28: TWh per GW
B29: Calibration factor rho | C29: =C24/C21 | E29: Eq. 7
B30: IEA energy per GW of capacity, 2030 | C30: =Inputs!$C$18/Inputs!$D$6 | D30: TWh per GW | E30: IEA 2030 / JLL 2030

Sheet Results
B2: Results (Sections 4 and 5.2)
B3: Every value is a formula. Green cells pull from other sheets.
B5: A. Central case, step by step
B6: Step | C6: Value | D6: Unit | E6: Formula
B7: Weighted utilisation | C7: =Utilisation!$F$12 | D7: share of time servers are working | E7: Utilisation sheet
B8: Idle power share | C8: =Inputs!$D$7 | D8: fraction of maximum power | E8: Inputs
B9: Electrical load factor | C9: =C8+(1-C8)*C7 | D9: fraction of maximum power | E9: idle + (1 - idle) x utilisation
B10: Calibration factor rho | C10: =Inputs!$D$11 | D10: ratio | E10: Calibration sheet
B11: IT energy | C11: =C10*Inputs!$D$6*C9*Inputs!$C$13/1000 | D11: TWh | E11: rho x capacity x load factor x hours / 1000
B12: Total facility energy | C12: =C11*Inputs!$D$8 | D12: TWh | E12: IT energy x PUE
B13: Emissions | C13: =C12*Inputs!$D$9/1000 | D13: Mt CO2 | E13: facility energy x grid intensity / 1000
B14: Direct water | C14: =C11*Inputs!$D$10/1000 | D14: trillion litres | E14: IT energy x WUE / 1000
B15: UNU implied combined intensity | C15: =Inputs!$C$17*1000/Inputs!$C$18 | D15: L per kWh | E15: UNU water / UNU energy
B16: Combined water (direct + generation) | C16: =C12*C15/1000 | D16: trillion litres | E16: facility energy x combined intensity / 1000
B17: Combined / direct ratio | C17: =C16/C14 | D17: x
B19: B. Results under the three PUE values (Section 4.1 table)
C20: New-build (low PUE) | D20: Blended fleet (central) | E20: Current fleet (high PUE) | F20: Unit
B21: PUE | C21: =Inputs!$C$8 | D21: =Inputs!$D$8 | E21: =Inputs!$E$8
B22: IT energy | C22: =$C$11 | D22: =$C$11 | E22: =$C$11 | F22: TWh
B23: Total facility energy | C23: =$C$11*Inputs!$C$8 | D23: =$C$11*Inputs!$D$8 | E23: =$C$11*Inputs!$E$8 | F23: TWh
B24: Emissions, static grid | C24: =$C$11*Inputs!$C$8*Inputs!$E$9/1000 | D24: =$C$11*Inputs!$D$8*Inputs!$E$9/1000 | E24: =$C$11*Inputs!$E$8*Inputs!$E$9/1000 | F24: Mt CO2
B25: Emissions, decarbonising grid | C25: =$C$11*Inputs!$C$8*Inputs!$C$9/1000 | D25: =$C$11*Inputs!$D$8*Inputs!$C$9/1000 | E25: =$C$11*Inputs!$E$8*Inputs!$C$9/1000 | F25: Mt CO2
B26: Direct water | C26: =$C$14 | D26: =$C$14 | E26: =$C$14 | F26: trillion litres
B29: C. Bundled scenarios (Section 4.2)
B30: Scenario | C30: Capacity (GW) | D30: Utilisation | E30: Idle share | F30: Load factor | G30: PUE | H30: Grid (g/kWh) | I30: WUE (L/kWh) | J30: rho | K30: IT energy (TWh) | L30: Facility energy (TWh) | M30: CO2 (Mt) | N30: Direct water (tn L) | O30: Combined water (tn L)
B31: Low impact | C31: =Inputs!$C$6 | D31: =Utilisation!$F$11 | E31: =Inputs!$C$7 | F31: =E31+(1-E31)*D31 | G31: =Inputs!$C$8 | H31: =Inputs!$C$9 | I31: =Inputs!$C$10 | J31: =Inputs!$C$11 | K31: =J31*C31*F31*Inputs!$C$13/1000 | L31: =K31*G31 | M31: =L31*H31/1000 | N31: =K31*I31/1000 | O31: =L31*$C$15/1000
B32: Central | C32: =Inputs!$D$6 | D32: =Utilisation!$F$12 | E32: =Inputs!$D$7 | F32: =E32+(1-E32)*D32 | G32: =Inputs!$D$8 | H32: =Inputs!$D$9 | I32: =Inputs!$D$10 | J32: =Inputs!$D$11 | K32: =J32*C32*F32*Inputs!$C$13/1000 | L32: =K32*G32 | M32: =L32*H32/1000 | N32: =K32*I32/1000 | O32: =L32*$C$15/1000
B33: High impact | C33: =Inputs!$E$6 | D33: =Utilisation!$F$13 | E33: =Inputs!$E$7 | F33: =E33+(1-E33)*D33 | G33: =Inputs!$E$8 | H33: =Inputs!$E$9 | I33: =Inputs!$E$10 | J33: =Inputs!$E$11 | K33: =J33*C33*F33*Inputs!$C$13/1000 | L33: =K33*G33 | M33: =L33*H33/1000 | N33: =K33*I33/1000 | O33: =L33*$C$15/1000
B36: D. One-at-a-time sensitivity, emissions (Section 4.2)
B37: Parameter varied | C37: Emissions at low end (Mt) | D37: Emissions at high end (Mt) | E37: Swing as % of central
B38: Base-year calibration (rho) | C38: =Inputs!$C$11*Inputs!$D$6*(Inputs!$D$7+(1-Inputs!$D$7)*Utilisation!$F$12)*Inputs!$C$13/1000*Inputs!$D$8*Inputs!$D$9/1000 | D38: =Inputs!$E$11*Inputs!$D$6*(Inputs!$D$7+(1-Inputs!$D$7)*Utilisation!$F$12)*Inputs!$C$13/1000*Inputs!$D$8*Inputs!$D$9/1000 | E38: =(D38-C38)/$C$13
B39: PUE | C39: =Inputs!$D$11*Inputs!$D$6*(Inputs!$D$7+(1-Inputs!$D$7)*Utilisation!$F$12)*Inputs!$C$13/1000*Inputs!$C$8*Inputs!$D$9/1000 | D39: =Inputs!$D$11*Inputs!$D$6*(Inputs!$D$7+(1-Inputs!$D$7)*Utilisation!$F$12)*Inputs!$C$13/1000*Inputs!$E$8*Inputs!$D$9/1000 | E39: =(D39-C39)/$C$13
B40: Grid carbon intensity | C40: =Inputs!$D$11*Inputs!$D$6*(Inputs!$D$7+(1-Inputs!$D$7)*Utilisation!$F$12)*Inputs!$C$13/1000*Inputs!$D$8*Inputs!$C$9/1000 | D40: =Inputs!$D$11*Inputs!$D$6*(Inputs!$D$7+(1-Inputs!$D$7)*Utilisation!$F$12)*Inputs!$C$13/1000*Inputs!$D$8*Inputs!$E$9/1000 | E40: =(D40-C40)/$C$13
B41: Capacity | C41: =Inputs!$D$11*Inputs!$C$6*(Inputs!$D$7+(1-Inputs!$D$7)*Utilisation!$F$12)*Inputs!$C$13/1000*Inputs!$D$8*Inputs!$D$9/1000 | D41: =Inputs!$D$11*Inputs!$E$6*(Inputs!$D$7+(1-Inputs!$D$7)*Utilisation!$F$12)*Inputs!$C$13/1000*Inputs!$D$8*Inputs!$D$9/1000 | E41: =(D41-C41)/$C$13
B42: Idle power share | C42: =Inputs!$D$11*Inputs!$D$6*(Inputs!$C$7+(1-Inputs!$C$7)*Utilisation!$F$12)*Inputs!$C$13/1000*Inputs!$D$8*Inputs!$D$9/1000 | D42: =Inputs!$D$11*Inputs!$D$6*(Inputs!$E$7+(1-Inputs!$E$7)*Utilisation!$F$12)*Inputs!$C$13/1000*Inputs!$D$8*Inputs!$D$9/1000 | E42: =(D42-C42)/$C$13
B43: Utilisation | C43: =Inputs!$D$11*Inputs!$D$6*(Inputs!$D$7+(1-Inputs!$D$7)*Utilisation!$F$11)*Inputs!$C$13/1000*Inputs!$D$8*Inputs!$D$9/1000 | D43: =Inputs!$D$11*Inputs!$D$6*(Inputs!$D$7+(1-Inputs!$D$7)*Utilisation!$F$13)*Inputs!$C$13/1000*Inputs!$D$8*Inputs!$D$9/1000 | E43: =(D43-C43)/$C$13
B45: Water swing (trillion litres)
B46: Parameter varied | C46: Low end | D46: High end | E46: Swing
B47: WUE | C47: =$C$11*Inputs!$C$10/1000 | D47: =$C$11*Inputs!$E$10/1000 | E47: =D47-C47
B48: Capacity | C48: =$C$10*Inputs!$C$6*$C$9*Inputs!$C$13/1000*Inputs!$D$10/1000 | D48: =$C$10*Inputs!$E$6*$C$9*Inputs!$C$13/1000*Inputs!$D$10/1000 | E48: =D48-C48
...
